---
{"title":"20 异常","note_type":"knowledge_base","description":"学习《csharp 图解教程》的学习笔记","tags":["csharp"],"create_time":"2024-05-24","update_time":"2025-02-19","dg-home":false,"dg-publish":true,"aliase":null,"root":"csharp 图解教程","permalink":"/04-知识仓库/知识单元/05-学习笔记/csharp 图解编程/20 异常/","dgPassFrontmatter":true,"noteIcon":"","created":"2024-05-24","updated":"2025-02-19"}
---


所属知识库：[[04-知识仓库/归纳目录/05-学习笔记/csharp 图解教程\|csharp 图解教程]]

### 1 什么是异常

异常是程序中的运行时错误，它违反了系统约束或应用程序约束，或出现了在正常操作时未预料的情形。

### 2 异常捕获

#### 2.1 try 语句

try 语句用来指明为避免出现异常而被保护的代码段，并在发生异常时提供代码处理异常。try 语句由 3 个部分组成，

1. try 块包含为避免出现异常而被保护的代码
2. catch 子句部分含有一个或多个 catch 子句。这些是处理异常的代码段，它们也称为是异常处理程序
3. finally 块含有在所有情况下都要被执行的代码，无论有没有异常发生

#### 2.2 异常类

有许多不同类型的异常可以在程序中发生。BCL 定义了许多类，每一个类代表一个指定的异常类型。当一个异常发生时，CLR:

1. 创建该类型的异常对象
2. 寻找适当的 catch 子句以处理它

异常类中的属性

| 属性           | 类型      | 描述                      |
| -------------- | --------- | ------------------------- |
| Message        | string    | 解释异常原因的消息        |
| StackTrace     | string    | 发生在何处                |
| InnerException | Exception | 前一个异常的引用          |
| HelpLink       | string    | 为异常原因提供 URN 或 URL |
| Source         | string    | 异常所在程序集的名称      |

#### 2.3 catch 子句

```csharp
catch {}
catch (ExceptionType) {}
catch (ExceptionType e) {}
```

1. 一般 catch 子句能接受任何异常，但不能确定引发异常的类型。这只允许对任何可能发生的异常的普通处理和清理。
2. 特定 catch 子句形式把一个异常类的名称作为参数。它匹配该指定类或派生自它的异常类的异常。
3. 带对象的特定 catch 子句提供关于异常的最多信息。它匹配该指定类的异常，或派生自它的异常类的异常。

```csharp
int x=10;
try
{
    int y=0;
    x/=y;
}
catch(DivideByZeroException e)
{
    Console.WriteLine("Message: {0}",e.Message);
    Console.WriteLine("Source:  {0}",e.Source);
    Console.WriteLine("Stack:   {0}",e.StackTrace);
}
```

#### 2.4 catch 子句段

当异常发生时，系统按顺序搜索 catch 子句的列表，第一个匹配该异常对象类型的 catch 子句被执行。因此，catch 子句的排序有两个重要的规则。具体如下。

1. 特定 catch 子句必须以一种顺序排列，最明确的异常类型第一，直到最普通的类型。例如，如果声明了一个派生自 NullReferenceException 的异常类，那么派生异常类型的 catch 子句应该被列在 NullReferenceException 的 catch 子句之前
2. 如果有一个一般 catch 子句，它必须是最后一个，并且在所有特定 catch 子句之后。不鼓励使用一般 catch 子句.因为它允许程序继续执行隐藏错误，让程序处于一种未知的状态。应尽可能使用特定 catch 子句

#### 2.5 finally 块

如果程序的控制流进人了一个带 finally 块的 try 语句，那么 finally 始终会被执行。

1. 如果在 try 块内部没有异常发生，那么在 try 块的结尾，控制流跳过任何 catch 子句并到 finally 块
2. 如果在 try 块内部发生了异常，那么在 catch 子句段中无论哪一个适当的 catch 子句被执行，接着就是 finally 块的执行

### 3 抛出异常

可以使用 throw 语句使代码显式地引发一个异常。throw 语句的语法 `throw ExceptionObject;`

eg:

```csharp
class MyClass
{
    public static void PrintArg(string arg)
    {
        try
        {
            if(arg==null)
            {
                var myEx=new ArgumentNullException("arg");
                throw myEx;
            }
            Console.WriteLine(arg);
        }
        catch(ArgumentNullException e)
        {
            Console.WriteLine("Message:  {0}",e.Message);
        }
    }
}
class Program
{
    static void Main()
    {
        string s=null;
        MyClass.PrintArg(s);
        MyClass.PrintArg("Hi there!");
    }
}
```

#### 3,1 不带异常对象的抛出

throw 语句还可以不带异常对象使用，在 catch 块内部。

1. 这种形式重新抛出当前异常，系统继续它的搜索，为该异常寻找另外的处理代码
2. 这种形式只能用在 catch 语句内部

eg:

```csharp
class MyClass
{
    public static void PrintArg(string arg)
    {
        try
        {
            try
            {
                if(arg==null)
                {
                    var myEx=new ArgumentNullException("arg");
                    throw myEx;
                }
                Console.WriteLine(arg);
            }
            catch(ArgumentNullException e)
            {
                Console.WriteLine("Inner Catch:  {0}",e.Message);
                throw;
            }
        }
        catch
        {
            Console.WriteLine("Outer Catch:  Handling an Exception.");
        }
    }
}
class Program
{
    static void Main()
    {
        string s=null;
        MyClass.PrintArg(s);
    }
}
```
